{"name": "Проверка появления сообщения об ошибки при невалидном значении", "status": "passed", "description": "Тест проверяет появление ошибки при разных невалидных значения", "steps": [{"name": "Открытие раздела Asynchronous Operation", "status": "passed", "start": 1760795533164, "stop": 1760795533308}, {"name": "Удаление значения из поля", "status": "passed", "start": 1760795533308, "stop": 1760795533375}, {"name": "Ввод значения", "status": "passed", "parameters": [{"name": "value", "value": "25"}], "start": 1760795533375, "stop": 1760795533397}, {"name": "Получение текста из сообщения об ошибки", "status": "passed", "start": 1760795533397, "stop": 1760795533411}], "parameters": [{"name": "value", "value": "25"}, {"name": "expected_message", "value": "''"}], "start": 1760795533164, "stop": 1760795533411, "uuid": "2d81d75b-d856-4144-9e72-12bd1a9fc5f6", "historyId": "0b913f3d5e1b68729186b372eba02295", "testCaseId": "6ee181214c8e63f33f13238776036c26", "fullName": "tests.test_asynchronous_operation_page#test_invalid_value", "labels": [{"name": "suite", "value": "Data loading"}, {"name": "parentSuite", "value": "tests"}, {"name": "host", "value": "OGPC214"}, {"name": "thread", "value": "22532-MainThread"}, {"name": "framework", "value": "pytest"}, {"name": "language", "value": "cpython3"}, {"name": "package", "value": "tests.test_asynchronous_operation_page"}], "titlePath": ["tests", "test_asynchronous_operation_page.py"]}